File: sample data/2theta_omega.csv
[Measurement conditions]
Sample identification,
Comment - 1,"Configuration=5-axis Cradle safety limit, Owner=User, Creation date=2021/03/24 15:36:14"
Comment - 2,"Goniometer=Theta/Theta; Minimum step size 2Theta:0.0001; Minimum step size Omega:0.0001"
Comment - 3,"Sample stage=Chi-Phi-x-y-z stage 240 mm; Minimum step size Phi:0.01; Minimum step size Chi:0.01; Minimum step size X:0.01; Minimum step size Y:0.01; Minimum step size Z:0.001"
Comment - 4,"Diffractometer system=EMPYREAN"
Comment - 5,"Measurement program=C:\Users\User\Documents\User\Shimomura lab\program_shimomura lab\TiO2-LAO 2t-w 20-90 Ge220 dcore.xrdmp, Identifier={4F83D392-D46F-473C-9A04-935A26DDC74A}"
Comment - 6,"Fine Calibration Offset for 2Theta = 0.0130 deg"
Anode material,Cu
K-Alpha1 wavelength,1.5405980
K-Alpha2 wavelength,1.5444260
Ratio K-Alpha2/K-Alpha1,0.000
Divergence slit,Fixed,0.76mm
Monochromator used,YES
Generator voltage, 45
Tube current, 40
File date and time,25/7/2022 10:29
Unit cell,
h k l, 0 0 0
Scan axis,2Theta-Omega
Scan range,20.00000,90.00000
Scan step size,0.0200000
Omega offset,0.0000
No. of points, 3500
Scan type,CONTINUOUS
Phi,0.00
Psi,0.00
X,0.00
Y,0.00
Z,9.338
Time per step,0.176
[Scan points]
Angle, TimePerStep, Intensity, ESD
20.01000, 0.176, 3.0, 1.7321
20.07000, 0.176, 1.0, 1.0000
20.13000, 0.176, 5.0, 2.2361
20.19000, 0.176, 4.0, 2.0000
20.25000, 0.176, 2.0, 1.4142
20.31000, 0.176, 4.0, 2.0000
20.37000, 0.176, 0.0, 0.0000
20.43000, 0.176, 4.0, 2.0000
20.49000, 0.176, 2.0, 1.4142
20.55000, 0.176, 1.0, 1.0000
20.61000, 0.176, 5.0, 2.2361
20.67000, 0.176, 4.0, 2.0000
20.73000, 0.176, 2.0, 1.4142
20.79000, 0.176, 8.0, 2.8284
20.85000, 0.176, 6.0, 2.4495
20.91000, 0.176, 5.0, 2.2361
20.97000, 0.176, 2.0, 1.4142
21.03000, 0.176, 3.0, 1.7321
21.09000, 0.176, 2.0, 1.4142
21.15000, 0.176, 6.0, 2.4495
21.21000, 0.176, 1.0, 1.0000
21.27000, 0.176, 2.0, 1.4142
21.33000, 0.176, 3.0, 1.7321
21.39000, 0.176, 0.0, 0.0000
21.45000, 0.176, 4.0, 2.0000
21.51000, 0.176, 2.0, 1.4142
21.57000, 0.176, 2.0, 1.4142
21.63000, 0.176, 3.0, 1.7321
21.69000, 0.176, 2.0, 1.4142
21.75000, 0.176, 6.0, 2.4495
21.81000, 0.176, 2.0, 1.4142
21.87000, 0.176, 6.0, 2.4495
21.93000, 0.176, 4.0, 2.0000
21.99000, 0.176, 7.0, 2.6458
22.05000, 0.176, 4.0, 2.0000
22.11000, 0.176, 6.0, 2.4495
22.17000, 0.176, 5.0, 2.2361
22.23000, 0.176, 6.0, 2.4495
22.29000, 0.176, 11.0, 3.3166
22.35000, 0.176, 5.0, 2.2361
22.41000, 0.176, 6.0, 2.4495
22.47000, 0.176, 6.0, 2.4495
22.53000, 0.176, 11.0, 3.3166
22.59000, 0.176, 16.0, 4.0000
22.65000, 0.176, 16.0, 4.0000
22.71000, 0.176, 10.0, 3.1623
22.77000, 0.176, 22.0, 4.6904
22.83000, 0.176, 27.0, 5.1962
22.89000, 0.176, 33.0, 5.7446
22.95000, 0.176, 43.0, 6.5574
23.01000, 0.176, 46.0, 6.7823
23.07000, 0.176, 99.0, 9.9499
23.13000, 0.176, 134.0, 11.5758
23.19000, 0.176, 299.0, 17.2916
23.25000, 0.176, 1573.0, 39.6611
23.31000, 0.176, 43850.0, 209.4039
23.37000, 0.176, 41574.0, 203.8970
23.43000, 0.176, 35163.0, 187.5180
23.49000, 0.176, 34055.0, 184.5400
23.55000, 0.176, 9572.0, 97.8366
23.61000, 0.176, 608.0, 24.6577
23.67000, 0.176, 196.0, 14.0000
23.73000, 0.176, 112.0, 10.5830
23.79000, 0.176, 59.0, 7.6811
23.85000, 0.176, 53.0, 7.2801
23.91000, 0.176, 45.0, 6.7082
23.97000, 0.176, 22.0, 4.6904
24.03000, 0.176, 16.0, 4.0000
24.09000, 0.176, 16.0, 4.0000
24.15000, 0.176, 10.0, 3.1623
24.21000, 0.176, 9.0, 3.0000
24.27000, 0.176, 8.0, 2.8284
24.33000, 0.176, 10.0, 3.1623
24.39000, 0.176, 7.0, 2.6458
24.45000, 0.176, 9.0, 3.0000
24.51000, 0.176, 7.0, 2.6458
24.57000, 0.176, 3.0, 1.7321
24.63000, 0.176, 3.0, 1.7321
24.69000, 0.176, 7.0, 2.6458
24.75000, 0.176, 4.0, 2.0000
24.81000, 0.176, 4.0, 2.0000
24.87000, 0.176, 5.0, 2.2361
24.93000, 0.176, 4.0, 2.0000
24.99000, 0.176, 1.0, 1.0000
25.05000, 0.176, 9.0, 3.0000
25.11000, 0.176, 9.0, 3.0000
25.17000, 0.176, 15.0, 3.8730
25.23000, 0.176, 6.0, 2.4495
25.29000, 0.176, 9.0, 3.0000
25.35000, 0.176, 5.0, 2.2361
25.41000, 0.176, 6.0, 2.4495
25.47000, 0.176, 3.0, 1.7321
25.53000, 0.176, 5.0, 2.2361
25.59000, 0.176, 3.0, 1.7321
25.65000, 0.176, 5.0, 2.2361
25.71000, 0.176, 2.0, 1.4142
25.77000, 0.176, 2.0, 1.4142
25.83000, 0.176, 5.0, 2.2361
25.89000, 0.176, 0.0, 0.0000
25.95000, 0.176, 5.0, 2.2361
26.01000, 0.176, 1.0, 1.0000
26.07000, 0.176, 3.0, 1.7321
26.13000, 0.176, 2.0, 1.4142
26.19000, 0.176, 3.0, 1.7321
26.25000, 0.176, 3.0, 1.7321
26.31000, 0.176, 4.0, 2.0000
26.37000, 0.176, 5.0, 2.2361
26.43000, 0.176, 4.0, 2.0000
26.49000, 0.176, 8.0, 2.8284
26.55000, 0.176, 2.0, 1.4142
26.61000, 0.176, 9.0, 3.0000
26.67000, 0.176, 5.0, 2.2361
26.73000, 0.176, 2.0, 1.4142
26.79000, 0.176, 2.0, 1.4142
26.85000, 0.176, 3.0, 1.7321
26.91000, 0.176, 0.0, 0.0000
26.97000, 0.176, 3.0, 1.7321
27.03000, 0.176, 3.0, 1.7321
27.09000, 0.176, 4.0, 2.0000
27.15000, 0.176, 4.0, 2.0000
27.21000, 0.176, 3.0, 1.7321
27.27000, 0.176, 4.0, 2.0000
27.33000, 0.176, 2.0, 1.4142
27.39000, 0.176, 3.0, 1.7321
27.45000, 0.176, 3.0, 1.7321
27.51000, 0.176, 3.0, 1.7321
27.57000, 0.176, 4.0, 2.0000
27.63000, 0.176, 4.0, 2.0000
27.69000, 0.176, 1.0, 1.0000
27.75000, 0.176, 3.0, 1.7321
27.81000, 0.176, 4.0, 2.0000
27.87000, 0.176, 4.0, 2.0000
27.93000, 0.176, 3.0, 1.7321
27.99000, 0.176, 1.0, 1.0000
28.05000, 0.176, 2.0, 1.4142
28.11000, 0.176, 3.0, 1.7321
28.17000, 0.176, 1.0, 1.0000
28.23000, 0.176, 3.0, 1.7321
28.29000, 0.176, 5.0, 2.2361
28.35000, 0.176, 5.0, 2.2361
28.41000, 0.176, 1.0, 1.0000
28.47000, 0.176, 1.0, 1.0000
28.53000, 0.176, 2.0, 1.4142
28.59000, 0.176, 2.0, 1.4142
28.65000, 0.176, 3.0, 1.7321
28.71000, 0.176, 5.0, 2.2361
28.77000, 0.176, 4.0, 2.0000
28.83000, 0.176, 3.0, 1.7321
28.89000, 0.176, 5.0, 2.2361
28.95000, 0.176, 5.0, 2.2361
29.01000, 0.176, 2.0, 1.4142
29.07000, 0.176, 4.0, 2.0000
29.13000, 0.176, 1.0, 1.0000
29.19000, 0.176, 2.0, 1.4142
29.25000, 0.176, 4.0, 2.0000
29.31000, 0.176, 5.0, 2.2361
29.37000, 0.176, 2.0, 1.4142
29.43000, 0.176, 5.0, 2.2361
29.49000, 0.176, 5.0, 2.2361
29.55000, 0.176, 3.0, 1.7321
29.61000, 0.176, 6.0, 2.4495
29.67000, 0.176, 4.0, 2.0000
29.73000, 0.176, 2.0, 1.4142
29.79000, 0.176, 8.0, 2.8284
29.85000, 0.176, 6.0, 2.4495
29.91000, 0.176, 6.0, 2.4495
29.97000, 0.176, 3.0, 1.7321
30.03000, 0.176, 3.0, 1.7321
30.09000, 0.176, 4.0, 2.0000
30.15000, 0.176, 4.0, 2.0000
30.21000, 0.176, 4.0, 2.0000
30.27000, 0.176, 7.0, 2.6458
30.33000, 0.176, 3.0, 1.7321
30.39000, 0.176, 0.0, 0.0000
30.45000, 0.176, 1.0, 1.0000
30.51000, 0.176, 2.0, 1.4142
30.57000, 0.176, 4.0, 2.0000
30.63000, 0.176, 5.0, 2.2361
30.69000, 0.176, 4.0, 2.0000
30.75000, 0.176, 4.0, 2.0000
30.81000, 0.176, 1.0, 1.0000
30.87000, 0.176, 8.0, 2.8284
30.93000, 0.176, 4.0, 2.0000
30.99000, 0.176, 0.0, 0.0000
31.05000, 0.176, 3.0, 1.7321
31.11000, 0.176, 5.0, 2.2361
31.17000, 0.176, 2.0, 1.4142
31.23000, 0.176, 4.0, 2.0000
31.29000, 0.176, 1.0, 1.0000
31.35000, 0.176, 4.0, 2.0000
31.41000, 0.176, 3.0, 1.7321
31.47000, 0.176, 1.0, 1.0000
31.53000, 0.176, 2.0, 1.4142
31.59000, 0.176, 4.0, 2.0000
31.65000, 0.176, 3.0, 1.7321
31.71000, 0.176, 6.0, 2.4495
31.77000, 0.176, 4.0, 2.0000
31.83000, 0.176, 4.0, 2.0000
31.89000, 0.176, 1.0, 1.0000
31.95000, 0.176, 3.0, 1.7321
32.01000, 0.176, 5.0, 2.2361
32.07000, 0.176, 0.0, 0.0000
32.13000, 0.176, 3.0, 1.7321
32.19000, 0.176, 5.0, 2.2361
32.25000, 0.176, 5.0, 2.2361
32.31000, 0.176, 1.0, 1.0000
32.37000, 0.176, 5.0, 2.2361
32.43000, 0.176, 3.0, 1.7321
32.49000, 0.176, 2.0, 1.4142
32.55000, 0.176, 6.0, 2.4495
32.61000, 0.176, 3.0, 1.7321
32.67000, 0.176, 3.0, 1.7321
32.73000, 0.176, 8.0, 2.8284
32.79000, 0.176, 5.0, 2.2361
32.85000, 0.176, 4.0, 2.0000
32.91000, 0.176, 2.0, 1.4142
32.97000, 0.176, 2.0, 1.4142
33.03000, 0.176, 1.0, 1.0000
33.09000, 0.176, 2.0, 1.4142
33.15000, 0.176, 2.0, 1.4142
33.21000, 0.176, 2.0, 1.4142
33.27000, 0.176, 3.0, 1.7321
33.33000, 0.176, 2.0, 1.4142
33.39000, 0.176, 6.0, 2.4495
33.45000, 0.176, 5.0, 2.2361
33.51000, 0.176, 5.0, 2.2361
33.57000, 0.176, 4.0, 2.0000
33.63000, 0.176, 3.0, 1.7321
33.69000, 0.176, 5.0, 2.2361
33.75000, 0.176, 1.0, 1.0000
33.81000, 0.176, 1.0, 1.0000
33.87000, 0.176, 2.0, 1.4142
33.93000, 0.176, 5.0, 2.2361
33.99000, 0.176, 3.0, 1.7321
34.05000, 0.176, 6.0, 2.4495
34.11000, 0.176, 6.0, 2.4495
34.17000, 0.176, 5.0, 2.2361
34.23000, 0.176, 3.0, 1.7321
34.29000, 0.176, 3.0, 1.7321
34.35000, 0.176, 2.0, 1.4142
34.41000, 0.176, 5.0, 2.2361
34.47000, 0.176, 7.0, 2.6458
34.53000, 0.176, 2.0, 1.4142
34.59000, 0.176, 2.0, 1.4142
34.65000, 0.176, 4.0, 2.0000
34.71000, 0.176, 6.0, 2.4495
34.77000, 0.176, 6.0, 2.4495
34.83000, 0.176, 8.0, 2.8284
34.89000, 0.176, 4.0, 2.0000
34.95000, 0.176, 8.0, 2.8284
35.01000, 0.176, 6.0, 2.4495
35.07000, 0.176, 3.0, 1.7321
35.13000, 0.176, 6.0, 2.4495
35.19000, 0.176, 7.0, 2.6458
35.25000, 0.176, 2.0, 1.4142
35.31000, 0.176, 3.0, 1.7321
35.37000, 0.176, 3.0, 1.7321
35.43000, 0.176, 6.0, 2.4495
35.49000, 0.176, 5.0, 2.2361
35.55000, 0.176, 5.0, 2.2361
35.61000, 0.176, 2.0, 1.4142
35.67000, 0.176, 6.0, 2.4495
35.73000, 0.176, 4.0, 2.0000
35.79000, 0.176, 5.0, 2.2361
35.85000, 0.176, 4.0, 2.0000
35.91000, 0.176, 2.0, 1.4142
35.97000, 0.176, 3.0, 1.7321
36.03000, 0.176, 3.0, 1.7321
36.09000, 0.176, 6.0, 2.4495
36.15000, 0.176, 6.0, 2.4495
36.21000, 0.176, 6.0, 2.4495
36.27000, 0.176, 7.0, 2.6458
36.33000, 0.176, 8.0, 2.8284
36.39000, 0.176, 4.0, 2.0000
36.45000, 0.176, 7.0, 2.6458
36.51000, 0.176, 9.0, 3.0000
36.57000, 0.176, 9.0, 3.0000
36.63000, 0.176, 12.0, 3.4641
36.69000, 0.176, 6.0, 2.4495
36.75000, 0.176, 9.0, 3.0000
36.81000, 0.176, 8.0, 2.8284
36.87000, 0.176, 16.0, 4.0000
36.93000, 0.176, 14.0, 3.7417
36.99000, 0.176, 13.0, 3.6056
37.05000, 0.176, 17.0, 4.1231
37.11000, 0.176, 24.0, 4.8990
37.17000, 0.176, 23.0, 4.7958
37.23000, 0.176, 29.0, 5.3852
37.29000, 0.176, 42.0, 6.4807
37.35000, 0.176, 51.0, 7.1414
37.41000, 0.176, 70.0, 8.3666
37.47000, 0.176, 108.0, 10.3923
37.53000, 0.176, 155.0, 12.4499
37.59000, 0.176, 253.0, 15.9060
37.65000, 0.176, 447.0, 21.1424
37.71000, 0.176, 852.0, 29.1890
37.77000, 0.176, 1437.0, 37.9078
37.83000, 0.176, 1857.0, 43.0929
37.89000, 0.176, 1805.0, 42.4853
37.95000, 0.176, 1352.0, 36.7696
38.01000, 0.176, 738.0, 27.1662
38.07000, 0.176, 329.0, 18.1384
38.13000, 0.176, 175.0, 13.2288
38.19000, 0.176, 100.0, 10.0000
38.25000, 0.176, 53.0, 7.2801
38.31000, 0.176, 38.0, 6.1644
38.37000, 0.176, 32.0, 5.6569
38.43000, 0.176, 29.0, 5.3852
38.49000, 0.176, 19.0, 4.3589
38.55000, 0.176, 18.0, 4.2426
38.61000, 0.176, 19.0, 4.3589
38.67000, 0.176, 12.0, 3.4641
38.73000, 0.176, 13.0, 3.6056
38.79000, 0.176, 6.0, 2.4495
38.85000, 0.176, 12.0, 3.4641
38.91000, 0.176, 6.0, 2.4495
38.97000, 0.176, 3.0, 1.7321
39.03000, 0.176, 7.0, 2.6458
39.09000, 0.176, 7.0, 2.6458
39.15000, 0.176, 8.0, 2.8284
39.21000, 0.176, 3.0, 1.7321
39.27000, 0.176, 9.0, 3.0000
39.33000, 0.176, 5.0, 2.2361
39.39000, 0.176, 3.0, 1.7321
39.45000, 0.176, 4.0, 2.0000
39.51000, 0.176, 7.0, 2.6458
39.57000, 0.176, 7.0, 2.6458
39.63000, 0.176, 2.0, 1.4142
39.69000, 0.176, 6.0, 2.4495
39.75000, 0.176, 6.0, 2.4495
39.81000, 0.176, 5.0, 2.2361
39.87000, 0.176, 6.0, 2.4495
39.93000, 0.176, 3.0, 1.7321
39.99000, 0.176, 5.0, 2.2361
40.05000, 0.176, 4.0, 2.0000
40.11000, 0.176, 2.0, 1.4142
40.17000, 0.176, 4.0, 2.0000
40.23000, 0.176, 5.0, 2.2361
40.29000, 0.176, 6.0, 2.4495
40.35000, 0.176, 2.0, 1.4142
40.41000, 0.176, 3.0, 1.7321
40.47000, 0.176, 2.0, 1.4142
40.53000, 0.176, 4.0, 2.0000
40.59000, 0.176, 3.0, 1.7321
40.65000, 0.176, 4.0, 2.0000
40.71000, 0.176, 2.0, 1.4142
40.77000, 0.176, 5.0, 2.2361
40.83000, 0.176, 8.0, 2.8284
40.89000, 0.176, 5.0, 2.2361
40.95000, 0.176, 3.0, 1.7321
41.01000, 0.176, 5.0, 2.2361
41.07000, 0.176, 7.0, 2.6458
41.13000, 0.176, 5.0, 2.2361
41.19000, 0.176, 2.0, 1.4142
41.25000, 0.176, 1.0, 1.0000
41.31000, 0.176, 7.0, 2.6458
41.37000, 0.176, 2.0, 1.4142
41.43000, 0.176, 5.0, 2.2361
41.49000, 0.176, 2.0, 1.4142
41.55000, 0.176, 5.0, 2.2361
41.61000, 0.176, 5.0, 2.2361
41.67000, 0.176, 7.0, 2.6458
41.73000, 0.176, 5.0, 2.2361
41.79000, 0.176, 7.0, 2.6458
41.85000, 0.176, 1.0, 1.0000
41.91000, 0.176, 3.0, 1.7321
41.97000, 0.176, 4.0, 2.0000
42.03000, 0.176, 0.0, 0.0000
42.09000, 0.176, 5.0, 2.2361
42.15000, 0.176, 3.0, 1.7321
42.21000, 0.176, 5.0, 2.2361
42.27000, 0.176, 3.0, 1.7321
42.33000, 0.176, 3.0, 1.7321
42.39000, 0.176, 3.0, 1.7321
42.45000, 0.176, 3.0, 1.7321
42.51000, 0.176, 1.0, 1.0000
42.57000, 0.176, 3.0, 1.7321
42.63000, 0.176, 8.0, 2.8284
42.69000, 0.176, 4.0, 2.0000
42.75000, 0.176, 3.0, 1.7321
42.81000, 0.176, 6.0, 2.4495
42.87000, 0.176, 4.0, 2.0000
42.93000, 0.176, 4.0, 2.0000
42.99000, 0.176, 2.0, 1.4142
43.05000, 0.176, 2.0, 1.4142
43.11000, 0.176, 4.0, 2.0000
43.17000, 0.176, 5.0, 2.2361
43.23000, 0.176, 4.0, 2.0000
43.29000, 0.176, 4.0, 2.0000
43.35000, 0.176, 2.0, 1.4142
43.41000, 0.176, 7.0, 2.6458
43.47000, 0.176, 2.0, 1.4142
43.53000, 0.176, 2.0, 1.4142
43.59000, 0.176, 1.0, 1.0000
43.65000, 0.176, 3.0, 1.7321
43.71000, 0.176, 6.0, 2.4495
43.77000, 0.176, 1.0, 1.0000
43.83000, 0.176, 6.0, 2.4495
43.89000, 0.176, 2.0, 1.4142
43.95000, 0.176, 2.0, 1.4142
44.01000, 0.176, 2.0, 1.4142
44.07000, 0.176, 5.0, 2.2361
44.13000, 0.176, 5.0, 2.2361
44.19000, 0.176, 2.0, 1.4142
44.25000, 0.176, 6.0, 2.4495
44.31000, 0.176, 5.0, 2.2361
44.37000, 0.176, 7.0, 2.6458
44.43000, 0.176, 0.0, 0.0000
44.49000, 0.176, 3.0, 1.7321
44.55000, 0.176, 4.0, 2.0000
44.61000, 0.176, 3.0, 1.7321
44.67000, 0.176, 3.0, 1.7321
44.73000, 0.176, 1.0, 1.0000
44.79000, 0.176, 1.0, 1.0000
44.85000, 0.176, 3.0, 1.7321
44.91000, 0.176, 3.0, 1.7321
44.97000, 0.176, 6.0, 2.4495
45.03000, 0.176, 6.0, 2.4495
45.09000, 0.176, 3.0, 1.7321
45.15000, 0.176, 3.0, 1.7321
45.21000, 0.176, 2.0, 1.4142
45.27000, 0.176, 5.0, 2.2361
45.33000, 0.176, 2.0, 1.4142
45.39000, 0.176, 5.0, 2.2361
45.45000, 0.176, 3.0, 1.7321
45.51000, 0.176, 2.0, 1.4142
45.57000, 0.176, 6.0, 2.4495
45.63000, 0.176, 2.0, 1.4142
45.69000, 0.176, 4.0, 2.0000
45.75000, 0.176, 5.0, 2.2361
45.81000, 0.176, 5.0, 2.2361
45.87000, 0.176, 1.0, 1.0000
45.93000, 0.176, 4.0, 2.0000
45.99000, 0.176, 4.0, 2.0000
46.05000, 0.176, 2.0, 1.4142
46.11000, 0.176, 8.0, 2.8284
46.17000, 0.176, 5.0, 2.2361
46.23000, 0.176, 11.0, 3.3166
46.29000, 0.176, 4.0, 2.0000
46.35000, 0.176, 10.0, 3.1623
46.41000, 0.176, 6.0, 2.4495
46.47000, 0.176, 5.0, 2.2361
46.53000, 0.176, 3.0, 1.7321
46.59000, 0.176, 7.0, 2.6458
46.65000, 0.176, 14.0, 3.7417
46.71000, 0.176, 8.0, 2.8284
46.77000, 0.176, 10.0, 3.1623
46.83000, 0.176, 12.0, 3.4641
46.89000, 0.176, 10.0, 3.1623
46.95000, 0.176, 16.0, 4.0000
47.01000, 0.176, 15.0, 3.8730
47.07000, 0.176, 21.0, 4.5826
47.13000, 0.176, 22.0, 4.6904
47.19000, 0.176, 25.0, 5.0000
47.25000, 0.176, 46.0, 6.7823
47.31000, 0.176, 52.0, 7.2111
47.37000, 0.176, 71.0, 8.4261
47.43000, 0.176, 78.0, 8.8318
47.49000, 0.176, 118.0, 10.8628
47.55000, 0.176, 184.0, 13.5647
47.61000, 0.176, 295.0, 17.1756
47.67000, 0.176, 542.0, 23.2809
47.73000, 0.176, 1574.0, 39.6737
47.79000, 0.176, 225299.0, 474.6567
47.85000, 0.176, 407080.0, 638.0282
47.91000, 0.176, 89395.0, 298.9900
47.97000, 0.176, 35290.0, 187.8563
48.03000, 0.176, 14653.0, 121.0496
48.09000, 0.176, 3310.0, 57.5326
48.15000, 0.176, 675.0, 25.9808
48.21000, 0.176, 237.0, 15.3948
48.27000, 0.176, 107.0, 10.3441
48.33000, 0.176, 68.0, 8.2462
48.39000, 0.176, 64.0, 8.0000
48.45000, 0.176, 38.0, 6.1644
48.51000, 0.176, 43.0, 6.5574
48.57000, 0.176, 27.0, 5.1962
48.63000, 0.176, 30.0, 5.4772
48.69000, 0.176, 12.0, 3.4641
48.75000, 0.176, 18.0, 4.2426
48.81000, 0.176, 11.0, 3.3166
48.87000, 0.176, 8.0, 2.8284
48.93000, 0.176, 6.0, 2.4495
48.99000, 0.176, 13.0, 3.6056
49.05000, 0.176, 6.0, 2.4495
49.11000, 0.176, 7.0, 2.6458
49.17000, 0.176, 7.0, 2.6458
49.23000, 0.176, 8.0, 2.8284
49.29000, 0.176, 12.0, 3.4641
49.35000, 0.176, 5.0, 2.2361
49.41000, 0.176, 2.0, 1.4142
49.47000, 0.176, 5.0, 2.2361
49.53000, 0.176, 6.0, 2.4495
49.59000, 0.176, 5.0, 2.2361
49.65000, 0.176, 3.0, 1.7321
49.71000, 0.176, 4.0, 2.0000
49.77000, 0.176, 2.0, 1.4142
49.83000, 0.176, 4.0, 2.0000
49.89000, 0.176, 10.0, 3.1623
49.95000, 0.176, 3.0, 1.7321
50.01000, 0.176, 4.0, 2.0000
50.07000, 0.176, 6.0, 2.4495
50.13000, 0.176, 1.0, 1.0000
50.19000, 0.176, 2.0, 1.4142
50.25000, 0.176, 4.0, 2.0000
50.31000, 0.176, 7.0, 2.6458
50.37000, 0.176, 4.0, 2.0000
50.43000, 0.176, 3.0, 1.7321
50.49000, 0.176, 4.0, 2.0000
50.55000, 0.176, 6.0, 2.4495
50.61000, 0.176, 5.0, 2.2361
50.67000, 0.176, 3.0, 1.7321
50.73000, 0.176, 2.0, 1.4142
50.79000, 0.176, 2.0, 1.4142
50.85000, 0.176, 2.0, 1.4142
50.91000, 0.176, 4.0, 2.0000
50.97000, 0.176, 3.0, 1.7321
51.03000, 0.176, 1.0, 1.0000
51.09000, 0.176, 4.0, 2.0000
51.15000, 0.176, 6.0, 2.4495
51.21000, 0.176, 0.0, 0.0000
51.27000, 0.176, 4.0, 2.0000
51.33000, 0.176, 2.0, 1.4142
51.39000, 0.176, 1.0, 1.0000
51.45000, 0.176, 5.0, 2.2361
51.51000, 0.176, 4.0, 2.0000
51.57000, 0.176, 5.0, 2.2361
51.63000, 0.176, 4.0, 2.0000
51.69000, 0.176, 5.0, 2.2361
51.75000, 0.176, 3.0, 1.7321
51.81000, 0.176, 4.0, 2.0000
51.87000, 0.176, 2.0, 1.4142
51.93000, 0.176, 2.0, 1.4142
51.99000, 0.176, 4.0, 2.0000
52.05000, 0.176, 0.0, 0.0000
52.11000, 0.176, 5.0, 2.2361
52.17000, 0.176, 8.0, 2.8284
52.23000, 0.176, 6.0, 2.4495
52.29000, 0.176, 2.0, 1.4142
52.35000, 0.176, 5.0, 2.2361
52.41000, 0.176, 3.0, 1.7321
52.47000, 0.176, 3.0, 1.7321
52.53000, 0.176, 6.0, 2.4495
52.59000, 0.176, 4.0, 2.0000
52.65000, 0.176, 3.0, 1.7321
52.71000, 0.176, 5.0, 2.2361
52.77000, 0.176, 2.0, 1.4142
52.83000, 0.176, 5.0, 2.2361
52.89000, 0.176, 1.0, 1.0000
52.95000, 0.176, 4.0, 2.0000
53.01000, 0.176, 4.0, 2.0000
53.07000, 0.176, 4.0, 2.0000
53.13000, 0.176, 3.0, 1.7321
53.19000, 0.176, 4.0, 2.0000
53.25000, 0.176, 3.0, 1.7321
53.31000, 0.176, 7.0, 2.6458
53.37000, 0.176, 6.0, 2.4495
53.43000, 0.176, 3.0, 1.7321
53.49000, 0.176, 1.0, 1.0000
53.55000, 0.176, 2.0, 1.4142
53.61000, 0.176, 3.0, 1.7321
53.67000, 0.176, 3.0, 1.7321
53.73000, 0.176, 5.0, 2.2361
53.79000, 0.176, 5.0, 2.2361
53.85000, 0.176, 5.0, 2.2361
53.91000, 0.176, 4.0, 2.0000
53.97000, 0.176, 8.0, 2.8284
54.03000, 0.176, 5.0, 2.2361
54.09000, 0.176, 3.0, 1.7321
54.15000, 0.176, 4.0, 2.0000
54.21000, 0.176, 3.0, 1.7321
54.27000, 0.176, 2.0, 1.4142
54.33000, 0.176, 7.0, 2.6458
54.39000, 0.176, 3.0, 1.7321
54.45000, 0.176, 3.0, 1.7321
54.51000, 0.176, 4.0, 2.0000
54.57000, 0.176, 6.0, 2.4495
54.63000, 0.176, 1.0, 1.0000
54.69000, 0.176, 4.0, 2.0000
54.75000, 0.176, 4.0, 2.0000
54.81000, 0.176, 7.0, 2.6458
54.87000, 0.176, 5.0, 2.2361
54.93000, 0.176, 0.0, 0.0000
54.99000, 0.176, 3.0, 1.7321
55.05000, 0.176, 5.0, 2.2361
55.11000, 0.176, 2.0, 1.4142
55.17000, 0.176, 3.0, 1.7321
55.23000, 0.176, 1.0, 1.0000
55.29000, 0.176, 6.0, 2.4495
55.35000, 0.176, 4.0, 2.0000
55.41000, 0.176, 3.0, 1.7321
55.47000, 0.176, 6.0, 2.4495
55.53000, 0.176, 2.0, 1.4142
55.59000, 0.176, 2.0, 1.4142
55.65000, 0.176, 2.0, 1.4142
55.71000, 0.176, 0.0, 0.0000
55.77000, 0.176, 8.0, 2.8284
55.83000, 0.176, 2.0, 1.4142
55.89000, 0.176, 3.0, 1.7321
55.95000, 0.176, 4.0, 2.0000
56.01000, 0.176, 3.0, 1.7321
56.07000, 0.176, 6.0, 2.4495
56.13000, 0.176, 3.0, 1.7321
56.19000, 0.176, 6.0, 2.4495
56.25000, 0.176, 4.0, 2.0000
56.31000, 0.176, 2.0, 1.4142
56.37000, 0.176, 5.0, 2.2361
56.43000, 0.176, 6.0, 2.4495
56.49000, 0.176, 6.0, 2.4495
56.55000, 0.176, 6.0, 2.4495
56.61000, 0.176, 3.0, 1.7321
56.67000, 0.176, 2.0, 1.4142
56.73000, 0.176, 2.0, 1.4142
56.79000, 0.176, 3.0, 1.7321
56.85000, 0.176, 5.0, 2.2361
56.91000, 0.176, 3.0, 1.7321
56.97000, 0.176, 3.0, 1.7321
57.03000, 0.176, 3.0, 1.7321
57.09000, 0.176, 3.0, 1.7321
57.15000, 0.176, 4.0, 2.0000
57.21000, 0.176, 3.0, 1.7321
57.27000, 0.176, 5.0, 2.2361
57.33000, 0.176, 1.0, 1.0000
57.39000, 0.176, 4.0, 2.0000
57.45000, 0.176, 3.0, 1.7321
57.51000, 0.176, 2.0, 1.4142
57.57000, 0.176, 2.0, 1.4142
57.63000, 0.176, 0.0, 0.0000
57.69000, 0.176, 3.0, 1.7321
57.75000, 0.176, 2.0, 1.4142
57.81000, 0.176, 2.0, 1.4142
57.87000, 0.176, 1.0, 1.0000
57.93000, 0.176, 2.0, 1.4142
57.99000, 0.176, 4.0, 2.0000
58.05000, 0.176, 4.0, 2.0000
58.11000, 0.176, 3.0, 1.7321
58.17000, 0.176, 5.0, 2.2361
58.23000, 0.176, 5.0, 2.2361
58.29000, 0.176, 6.0, 2.4495
58.35000, 0.176, 2.0, 1.4142
58.41000, 0.176, 3.0, 1.7321
58.47000, 0.176, 5.0, 2.2361
58.53000, 0.176, 2.0, 1.4142
58.59000, 0.176, 6.0, 2.4495
58.65000, 0.176, 5.0, 2.2361
58.71000, 0.176, 5.0, 2.2361
58.77000, 0.176, 2.0, 1.4142
58.83000, 0.176, 1.0, 1.0000
58.89000, 0.176, 6.0, 2.4495
58.95000, 0.176, 4.0, 2.0000
59.01000, 0.176, 6.0, 2.4495
59.07000, 0.176, 1.0, 1.0000
59.13000, 0.176, 4.0, 2.0000
59.19000, 0.176, 4.0, 2.0000
59.25000, 0.176, 3.0, 1.7321
59.31000, 0.176, 3.0, 1.7321
59.37000, 0.176, 2.0, 1.4142
59.43000, 0.176, 1.0, 1.0000
59.49000, 0.176, 4.0, 2.0000
59.55000, 0.176, 6.0, 2.4495
59.61000, 0.176, 2.0, 1.4142
59.67000, 0.176, 3.0, 1.7321
59.73000, 0.176, 1.0, 1.0000
59.79000, 0.176, 4.0, 2.0000
59.85000, 0.176, 3.0, 1.7321
59.91000, 0.176, 3.0, 1.7321
59.97000, 0.176, 2.0, 1.4142
60.03000, 0.176, 1.0, 1.0000
60.09000, 0.176, 4.0, 2.0000
60.15000, 0.176, 3.0, 1.7321
60.21000, 0.176, 4.0, 2.0000
60.27000, 0.176, 2.0, 1.4142
60.33000, 0.176, 7.0, 2.6458
60.39000, 0.176, 3.0, 1.7321
60.45000, 0.176, 5.0, 2.2361
60.51000, 0.176, 3.0, 1.7321
60.57000, 0.176, 4.0, 2.0000
60.63000, 0.176, 3.0, 1.7321
60.69000, 0.176, 3.0, 1.7321
60.75000, 0.176, 5.0, 2.2361
60.81000, 0.176, 0.0, 0.0000
60.87000, 0.176, 4.0, 2.0000
60.93000, 0.176, 3.0, 1.7321
60.99000, 0.176, 5.0, 2.2361
61.05000, 0.176, 2.0, 1.4142
61.11000, 0.176, 8.0, 2.8284
61.17000, 0.176, 6.0, 2.4495
61.23000, 0.176, 3.0, 1.7321
61.29000, 0.176, 4.0, 2.0000
61.35000, 0.176, 5.0, 2.2361
61.41000, 0.176, 3.0, 1.7321
61.47000, 0.176, 6.0, 2.4495
61.53000, 0.176, 6.0, 2.4495
61.59000, 0.176, 4.0, 2.0000
61.65000, 0.176, 5.0, 2.2361
61.71000, 0.176, 1.0, 1.0000
61.77000, 0.176, 1.0, 1.0000
61.83000, 0.176, 3.0, 1.7321
61.89000, 0.176, 1.0, 1.0000
61.95000, 0.176, 6.0, 2.4495
62.01000, 0.176, 2.0, 1.4142
62.07000, 0.176, 2.0, 1.4142
62.13000, 0.176, 3.0, 1.7321
62.19000, 0.176, 1.0, 1.0000
62.25000, 0.176, 4.0, 2.0000
62.31000, 0.176, 3.0, 1.7321
62.37000, 0.176, 2.0, 1.4142
62.43000, 0.176, 5.0, 2.2361
62.49000, 0.176, 4.0, 2.0000
62.55000, 0.176, 3.0, 1.7321
62.61000, 0.176, 2.0, 1.4142
62.67000, 0.176, 5.0, 2.2361
62.73000, 0.176, 4.0, 2.0000
62.79000, 0.176, 5.0, 2.2361
62.85000, 0.176, 3.0, 1.7321
62.91000, 0.176, 6.0, 2.4495
62.97000, 0.176, 7.0, 2.6458
63.03000, 0.176, 4.0, 2.0000
63.09000, 0.176, 5.0, 2.2361
63.15000, 0.176, 4.0, 2.0000
63.21000, 0.176, 2.0, 1.4142
63.27000, 0.176, 3.0, 1.7321
63.33000, 0.176, 3.0, 1.7321
63.39000, 0.176, 6.0, 2.4495
63.45000, 0.176, 6.0, 2.4495
63.51000, 0.176, 2.0, 1.4142
63.57000, 0.176, 3.0, 1.7321
63.63000, 0.176, 4.0, 2.0000
63.69000, 0.176, 3.0, 1.7321
63.75000, 0.176, 2.0, 1.4142
63.81000, 0.176, 6.0, 2.4495
63.87000, 0.176, 3.0, 1.7321
63.93000, 0.176, 6.0, 2.4495
63.99000, 0.176, 3.0, 1.7321
64.05000, 0.176, 2.0, 1.4142
64.11000, 0.176, 5.0, 2.2361
64.17000, 0.176, 5.0, 2.2361
64.23000, 0.176, 2.0, 1.4142
64.29000, 0.176, 3.0, 1.7321
64.35000, 0.176, 6.0, 2.4495
64.41000, 0.176, 7.0, 2.6458
64.47000, 0.176, 10.0, 3.1623
64.53000, 0.176, 2.0, 1.4142
64.59000, 0.176, 3.0, 1.7321
64.65000, 0.176, 2.0, 1.4142
64.71000, 0.176, 2.0, 1.4142
64.77000, 0.176, 3.0, 1.7321
64.83000, 0.176, 3.0, 1.7321
64.89000, 0.176, 2.0, 1.4142
64.95000, 0.176, 4.0, 2.0000
65.01000, 0.176, 5.0, 2.2361
65.07000, 0.176, 6.0, 2.4495
65.13000, 0.176, 4.0, 2.0000
65.19000, 0.176, 4.0, 2.0000
65.25000, 0.176, 3.0, 1.7321
65.31000, 0.176, 2.0, 1.4142
65.37000, 0.176, 8.0, 2.8284
65.43000, 0.176, 5.0, 2.2361
65.49000, 0.176, 2.0, 1.4142
65.55000, 0.176, 2.0, 1.4142
65.61000, 0.176, 2.0, 1.4142
65.67000, 0.176, 1.0, 1.0000
65.73000, 0.176, 4.0, 2.0000
65.79000, 0.176, 5.0, 2.2361
65.85000, 0.176, 4.0, 2.0000
65.91000, 0.176, 6.0, 2.4495
65.97000, 0.176, 5.0, 2.2361
66.03000, 0.176, 5.0, 2.2361
66.09000, 0.176, 6.0, 2.4495
66.15000, 0.176, 1.0, 1.0000
66.21000, 0.176, 8.0, 2.8284
66.27000, 0.176, 6.0, 2.4495
66.33000, 0.176, 6.0, 2.4495
66.39000, 0.176, 1.0, 1.0000
66.45000, 0.176, 4.0, 2.0000
66.51000, 0.176, 4.0, 2.0000
66.57000, 0.176, 6.0, 2.4495
66.63000, 0.176, 3.0, 1.7321
66.69000, 0.176, 4.0, 2.0000
66.75000, 0.176, 5.0, 2.2361
66.81000, 0.176, 1.0, 1.0000
66.87000, 0.176, 2.0, 1.4142
66.93000, 0.176, 4.0, 2.0000
66.99000, 0.176, 3.0, 1.7321
67.05000, 0.176, 2.0, 1.4142
67.11000, 0.176, 6.0, 2.4495
67.17000, 0.176, 7.0, 2.6458
67.23000, 0.176, 1.0, 1.0000
67.29000, 0.176, 2.0, 1.4142
67.35000, 0.176, 1.0, 1.0000
67.41000, 0.176, 4.0, 2.0000
67.47000, 0.176, 3.0, 1.7321
67.53000, 0.176, 3.0, 1.7321
67.59000, 0.176, 4.0, 2.0000
67.65000, 0.176, 4.0, 2.0000
67.71000, 0.176, 4.0, 2.0000
67.77000, 0.176, 5.0, 2.2361
67.83000, 0.176, 3.0, 1.7321
67.89000, 0.176, 4.0, 2.0000
67.95000, 0.176, 4.0, 2.0000
68.01000, 0.176, 3.0, 1.7321
68.07000, 0.176, 0.0, 0.0000
68.13000, 0.176, 4.0, 2.0000
68.19000, 0.176, 1.0, 1.0000
68.25000, 0.176, 6.0, 2.4495
68.31000, 0.176, 1.0, 1.0000
68.37000, 0.176, 5.0, 2.2361
68.43000, 0.176, 5.0, 2.2361
68.49000, 0.176, 6.0, 2.4495
68.55000, 0.176, 6.0, 2.4495
68.61000, 0.176, 3.0, 1.7321
68.67000, 0.176, 5.0, 2.2361
68.73000, 0.176, 3.0, 1.7321
68.79000, 0.176, 5.0, 2.2361
68.85000, 0.176, 6.0, 2.4495
68.91000, 0.176, 1.0, 1.0000
68.97000, 0.176, 7.0, 2.6458
69.03000, 0.176, 4.0, 2.0000
69.09000, 0.176, 5.0, 2.2361
69.15000, 0.176, 0.0, 0.0000
69.21000, 0.176, 8.0, 2.8284
69.27000, 0.176, 4.0, 2.0000
69.33000, 0.176, 1.0, 1.0000
69.39000, 0.176, 1.0, 1.0000
69.45000, 0.176, 5.0, 2.2361
69.51000, 0.176, 5.0, 2.2361
69.57000, 0.176, 2.0, 1.4142
69.63000, 0.176, 3.0, 1.7321
69.69000, 0.176, 3.0, 1.7321
69.75000, 0.176, 6.0, 2.4495
69.81000, 0.176, 6.0, 2.4495
69.87000, 0.176, 5.0, 2.2361
69.93000, 0.176, 2.0, 1.4142
69.99000, 0.176, 4.0, 2.0000
70.05000, 0.176, 4.0, 2.0000
70.11000, 0.176, 6.0, 2.4495
70.17000, 0.176, 5.0, 2.2361
70.23000, 0.176, 6.0, 2.4495
70.29000, 0.176, 4.0, 2.0000
70.35000, 0.176, 0.0, 0.0000
70.41000, 0.176, 2.0, 1.4142
70.47000, 0.176, 8.0, 2.8284
70.53000, 0.176, 4.0, 2.0000
70.59000, 0.176, 4.0, 2.0000
70.65000, 0.176, 4.0, 2.0000
70.71000, 0.176, 3.0, 1.7321
70.77000, 0.176, 5.0, 2.2361
70.83000, 0.176, 4.0, 2.0000
70.89000, 0.176, 0.0, 0.0000
70.95000, 0.176, 4.0, 2.0000
71.01000, 0.176, 3.0, 1.7321
71.07000, 0.176, 2.0, 1.4142
71.13000, 0.176, 3.0, 1.7321
71.19000, 0.176, 6.0, 2.4495
71.25000, 0.176, 2.0, 1.4142
71.31000, 0.176, 5.0, 2.2361
71.37000, 0.176, 3.0, 1.7321
71.43000, 0.176, 6.0, 2.4495
71.49000, 0.176, 2.0, 1.4142
71.55000, 0.176, 3.0, 1.7321
71.61000, 0.176, 6.0, 2.4495
71.67000, 0.176, 2.0, 1.4142
71.73000, 0.176, 4.0, 2.0000
71.79000, 0.176, 3.0, 1.7321
71.85000, 0.176, 4.0, 2.0000
71.91000, 0.176, 2.0, 1.4142
71.97000, 0.176, 1.0, 1.0000
72.03000, 0.176, 5.0, 2.2361
72.09000, 0.176, 2.0, 1.4142
72.15000, 0.176, 4.0, 2.0000
72.21000, 0.176, 1.0, 1.0000
72.27000, 0.176, 4.0, 2.0000
72.33000, 0.176, 2.0, 1.4142
72.39000, 0.176, 2.0, 1.4142
72.45000, 0.176, 2.0, 1.4142
72.51000, 0.176, 6.0, 2.4495
72.57000, 0.176, 3.0, 1.7321
72.63000, 0.176, 5.0, 2.2361
72.69000, 0.176, 3.0, 1.7321
72.75000, 0.176, 5.0, 2.2361
72.81000, 0.176, 3.0, 1.7321
72.87000, 0.176, 5.0, 2.2361
72.93000, 0.176, 1.0, 1.0000
72.99000, 0.176, 4.0, 2.0000
73.05000, 0.176, 1.0, 1.0000
73.11000, 0.176, 1.0, 1.0000
73.17000, 0.176, 0.0, 0.0000
73.23000, 0.176, 4.0, 2.0000
73.29000, 0.176, 9.0, 3.0000
73.35000, 0.176, 3.0, 1.7321
73.41000, 0.176, 6.0, 2.4495
73.47000, 0.176, 4.0, 2.0000
73.53000, 0.176, 7.0, 2.6458
73.59000, 0.176, 8.0, 2.8284
73.65000, 0.176, 1.0, 1.0000
73.71000, 0.176, 1.0, 1.0000
73.77000, 0.176, 7.0, 2.6458
73.83000, 0.176, 5.0, 2.2361
73.89000, 0.176, 8.0, 2.8284
73.95000, 0.176, 7.0, 2.6458
74.01000, 0.176, 2.0, 1.4142
74.07000, 0.176, 1.0, 1.0000
74.13000, 0.176, 8.0, 2.8284
74.19000, 0.176, 5.0, 2.2361
74.25000, 0.176, 4.0, 2.0000
74.31000, 0.176, 5.0, 2.2361
74.37000, 0.176, 7.0, 2.6458
74.43000, 0.176, 4.0, 2.0000
74.49000, 0.176, 11.0, 3.3166
74.55000, 0.176, 12.0, 3.4641
74.61000, 0.176, 11.0, 3.3166
74.67000, 0.176, 12.0, 3.4641
74.73000, 0.176, 31.0, 5.5678
74.79000, 0.176, 65.0, 8.0623
74.85000, 0.176, 102.0, 10.0995
74.91000, 0.176, 546.0, 23.3666
74.97000, 0.176, 46546.0, 215.7452
75.03000, 0.176, 101083.0, 317.9355
75.09000, 0.176, 6850.0, 82.7647
75.15000, 0.176, 2054.0, 45.3211
75.21000, 0.176, 948.0, 30.7896
75.27000, 0.176, 273.0, 16.5227
75.33000, 0.176, 113.0, 10.6301
75.39000, 0.176, 43.0, 6.5574
75.45000, 0.176, 17.0, 4.1231
75.51000, 0.176, 14.0, 3.7417
75.57000, 0.176, 5.0, 2.2361
75.63000, 0.176, 5.0, 2.2361
75.69000, 0.176, 4.0, 2.0000
75.75000, 0.176, 4.0, 2.0000
75.81000, 0.176, 3.0, 1.7321
75.87000, 0.176, 13.0, 3.6056
75.93000, 0.176, 5.0, 2.2361
75.99000, 0.176, 2.0, 1.4142
76.05000, 0.176, 5.0, 2.2361
76.11000, 0.176, 7.0, 2.6458
76.17000, 0.176, 3.0, 1.7321
76.23000, 0.176, 9.0, 3.0000
76.29000, 0.176, 8.0, 2.8284
76.35000, 0.176, 5.0, 2.2361
76.41000, 0.176, 6.0, 2.4495
76.47000, 0.176, 5.0, 2.2361
76.53000, 0.176, 4.0, 2.0000
76.59000, 0.176, 4.0, 2.0000
76.65000, 0.176, 8.0, 2.8284
76.71000, 0.176, 1.0, 1.0000
76.77000, 0.176, 4.0, 2.0000
76.83000, 0.176, 5.0, 2.2361
76.89000, 0.176, 6.0, 2.4495
76.95000, 0.176, 4.0, 2.0000
77.01000, 0.176, 3.0, 1.7321
77.07000, 0.176, 4.0, 2.0000
77.13000, 0.176, 7.0, 2.6458
77.19000, 0.176, 5.0, 2.2361
77.25000, 0.176, 5.0, 2.2361
77.31000, 0.176, 3.0, 1.7321
77.37000, 0.176, 3.0, 1.7321
77.43000, 0.176, 2.0, 1.4142
77.49000, 0.176, 7.0, 2.6458
77.55000, 0.176, 6.0, 2.4495
77.61000, 0.176, 3.0, 1.7321
77.67000, 0.176, 2.0, 1.4142
77.73000, 0.176, 4.0, 2.0000
77.79000, 0.176, 5.0, 2.2361
77.85000, 0.176, 5.0, 2.2361
77.91000, 0.176, 6.0, 2.4495
77.97000, 0.176, 1.0, 1.0000
78.03000, 0.176, 2.0, 1.4142
78.09000, 0.176, 2.0, 1.4142
78.15000, 0.176, 6.0, 2.4495
78.21000, 0.176, 2.0, 1.4142
78.27000, 0.176, 7.0, 2.6458
78.33000, 0.176, 7.0, 2.6458
78.39000, 0.176, 4.0, 2.0000
78.45000, 0.176, 6.0, 2.4495
78.51000, 0.176, 4.0, 2.0000
78.57000, 0.176, 2.0, 1.4142
78.63000, 0.176, 5.0, 2.2361
78.69000, 0.176, 4.0, 2.0000
78.75000, 0.176, 5.0, 2.2361
78.81000, 0.176, 1.0, 1.0000
78.87000, 0.176, 4.0, 2.0000
78.93000, 0.176, 0.0, 0.0000
78.99000, 0.176, 4.0, 2.0000
79.05000, 0.176, 4.0, 2.0000
79.11000, 0.176, 5.0, 2.2361
79.17000, 0.176, 2.0, 1.4142
79.23000, 0.176, 3.0, 1.7321
79.29000, 0.176, 4.0, 2.0000
79.35000, 0.176, 3.0, 1.7321
79.41000, 0.176, 2.0, 1.4142
79.47000, 0.176, 9.0, 3.0000
79.53000, 0.176, 10.0, 3.1623
79.59000, 0.176, 8.0, 2.8284
79.65000, 0.176, 6.0, 2.4495
79.71000, 0.176, 3.0, 1.7321
79.77000, 0.176, 3.0, 1.7321
79.83000, 0.176, 3.0, 1.7321
79.89000, 0.176, 3.0, 1.7321
79.95000, 0.176, 3.0, 1.7321
80.01000, 0.176, 4.0, 2.0000
80.07000, 0.176, 6.0, 2.4495
80.13000, 0.176, 4.0, 2.0000
80.19000, 0.176, 8.0, 2.8284
80.25000, 0.176, 5.0, 2.2361
80.31000, 0.176, 3.0, 1.7321
80.37000, 0.176, 7.0, 2.6458
80.43000, 0.176, 9.0, 3.0000
80.49000, 0.176, 6.0, 2.4495
80.55000, 0.176, 13.0, 3.6056
80.61000, 0.176, 14.0, 3.7417
80.67000, 0.176, 19.0, 4.3589
80.73000, 0.176, 16.0, 4.0000
80.79000, 0.176, 16.0, 4.0000
80.85000, 0.176, 28.0, 5.2915
80.91000, 0.176, 26.0, 5.0990
80.97000, 0.176, 31.0, 5.5678
81.03000, 0.176, 23.0, 4.7958
81.09000, 0.176, 30.0, 5.4772
81.15000, 0.176, 21.0, 4.5826
81.21000, 0.176, 14.0, 3.7417
81.27000, 0.176, 7.0, 2.6458
81.33000, 0.176, 10.0, 3.1623
81.39000, 0.176, 6.0, 2.4495
81.45000, 0.176, 3.0, 1.7321
81.51000, 0.176, 5.0, 2.2361
81.57000, 0.176, 7.0, 2.6458
81.63000, 0.176, 5.0, 2.2361
81.69000, 0.176, 6.0, 2.4495
81.75000, 0.176, 5.0, 2.2361
81.81000, 0.176, 6.0, 2.4495
81.87000, 0.176, 5.0, 2.2361
81.93000, 0.176, 3.0, 1.7321
81.99000, 0.176, 3.0, 1.7321
82.05000, 0.176, 5.0, 2.2361
82.11000, 0.176, 3.0, 1.7321
82.17000, 0.176, 7.0, 2.6458
82.23000, 0.176, 3.0, 1.7321
82.29000, 0.176, 5.0, 2.2361
82.35000, 0.176, 3.0, 1.7321
82.41000, 0.176, 6.0, 2.4495
82.47000, 0.176, 3.0, 1.7321
82.53000, 0.176, 4.0, 2.0000
82.59000, 0.176, 6.0, 2.4495
82.65000, 0.176, 2.0, 1.4142
82.71000, 0.176, 1.0, 1.0000
82.77000, 0.176, 6.0, 2.4495
82.83000, 0.176, 4.0, 2.0000
82.89000, 0.176, 5.0, 2.2361
82.95000, 0.176, 5.0, 2.2361
83.01000, 0.176, 2.0, 1.4142
83.07000, 0.176, 2.0, 1.4142
83.13000, 0.176, 4.0, 2.0000
83.19000, 0.176, 2.0, 1.4142
83.25000, 0.176, 3.0, 1.7321
83.31000, 0.176, 2.0, 1.4142
83.37000, 0.176, 1.0, 1.0000
83.43000, 0.176, 6.0, 2.4495
83.49000, 0.176, 3.0, 1.7321
83.55000, 0.176, 1.0, 1.0000
83.61000, 0.176, 3.0, 1.7321
83.67000, 0.176, 3.0, 1.7321
83.73000, 0.176, 2.0, 1.4142
83.79000, 0.176, 8.0, 2.8284
83.85000, 0.176, 5.0, 2.2361
83.91000, 0.176, 2.0, 1.4142
83.97000, 0.176, 4.0, 2.0000
84.03000, 0.176, 3.0, 1.7321
84.09000, 0.176, 4.0, 2.0000
84.15000, 0.176, 6.0, 2.4495
84.21000, 0.176, 4.0, 2.0000
84.27000, 0.176, 4.0, 2.0000
84.33000, 0.176, 2.0, 1.4142
84.39000, 0.176, 3.0, 1.7321
84.45000, 0.176, 3.0, 1.7321
84.51000, 0.176, 1.0, 1.0000
84.57000, 0.176, 5.0, 2.2361
84.63000, 0.176, 4.0, 2.0000
84.69000, 0.176, 5.0, 2.2361
84.75000, 0.176, 4.0, 2.0000
84.81000, 0.176, 3.0, 1.7321
84.87000, 0.176, 4.0, 2.0000
84.93000, 0.176, 3.0, 1.7321
84.99000, 0.176, 7.0, 2.6458
85.05000, 0.176, 7.0, 2.6458
85.11000, 0.176, 12.0, 3.4641
85.17000, 0.176, 3.0, 1.7321
85.23000, 0.176, 0.0, 0.0000
85.29000, 0.176, 5.0, 2.2361
85.35000, 0.176, 6.0, 2.4495
85.41000, 0.176, 5.0, 2.2361
85.47000, 0.176, 6.0, 2.4495
85.53000, 0.176, 6.0, 2.4495
85.59000, 0.176, 6.0, 2.4495
85.65000, 0.176, 3.0, 1.7321
85.71000, 0.176, 4.0, 2.0000
85.77000, 0.176, 4.0, 2.0000
85.83000, 0.176, 4.0, 2.0000
85.89000, 0.176, 6.0, 2.4495
85.95000, 0.176, 4.0, 2.0000
86.01000, 0.176, 5.0, 2.2361
86.07000, 0.176, 3.0, 1.7321
86.13000, 0.176, 4.0, 2.0000
86.19000, 0.176, 6.0, 2.4495
86.25000, 0.176, 6.0, 2.4495
86.31000, 0.176, 3.0, 1.7321
86.37000, 0.176, 5.0, 2.2361
86.43000, 0.176, 3.0, 1.7321
86.49000, 0.176, 6.0, 2.4495
86.55000, 0.176, 2.0, 1.4142
86.61000, 0.176, 5.0, 2.2361
86.67000, 0.176, 6.0, 2.4495
86.73000, 0.176, 1.0, 1.0000
86.79000, 0.176, 4.0, 2.0000
86.85000, 0.176, 7.0, 2.6458
86.91000, 0.176, 6.0, 2.4495
86.97000, 0.176, 4.0, 2.0000
87.03000, 0.176, 4.0, 2.0000
87.09000, 0.176, 2.0, 1.4142
87.15000, 0.176, 3.0, 1.7321
87.21000, 0.176, 3.0, 1.7321
87.27000, 0.176, 0.0, 0.0000
87.33000, 0.176, 1.0, 1.0000
87.39000, 0.176, 4.0, 2.0000
87.45000, 0.176, 2.0, 1.4142
87.51000, 0.176, 5.0, 2.2361
87.57000, 0.176, 3.0, 1.7321
87.63000, 0.176, 2.0, 1.4142
87.69000, 0.176, 2.0, 1.4142
87.75000, 0.176, 3.0, 1.7321
87.81000, 0.176, 2.0, 1.4142
87.87000, 0.176, 5.0, 2.2361
87.93000, 0.176, 6.0, 2.4495
87.99000, 0.176, 4.0, 2.0000
88.05000, 0.176, 4.0, 2.0000
88.11000, 0.176, 5.0, 2.2361
88.17000, 0.176, 3.0, 1.7321
88.23000, 0.176, 2.0, 1.4142
88.29000, 0.176, 5.0, 2.2361
88.35000, 0.176, 1.0, 1.0000
88.41000, 0.176, 4.0, 2.0000
88.47000, 0.176, 1.0, 1.0000
88.53000, 0.176, 1.0, 1.0000
88.59000, 0.176, 2.0, 1.4142
88.65000, 0.176, 4.0, 2.0000
88.71000, 0.176, 4.0, 2.0000
88.77000, 0.176, 6.0, 2.4495
88.83000, 0.176, 2.0, 1.4142
88.89000, 0.176, 1.0, 1.0000
88.95000, 0.176, 3.0, 1.7321
89.01000, 0.176, 4.0, 2.0000
89.07000, 0.176, 5.0, 2.2361
89.13000, 0.176, 3.0, 1.7321
89.19000, 0.176, 4.0, 2.0000
89.25000, 0.176, 2.0, 1.4142
89.31000, 0.176, 5.0, 2.2361
89.37000, 0.176, 3.0, 1.7321
89.43000, 0.176, 6.0, 2.4495
89.49000, 0.176, 1.0, 1.0000
89.55000, 0.176, 3.0, 1.7321
89.61000, 0.176, 5.0, 2.2361
89.67000, 0.176, 5.0, 2.2361
89.73000, 0.176, 0.0, 0.0000
89.79000, 0.176, 2.0, 1.4142
89.85000, 0.176, 8.0, 2.8284
89.91000, 0.176, 2.0, 1.4142
89.97000, 0.176, 5.0, 2.2361
89.99000, 0.176, 7.0, 2.6458